<?xml version="1.0"?>
<robot xmlns:xacro="http://www.ros.org/wiki/xacro" name="urdf_tutorial">

    <!-- MACROS -->
    <xacro:include filename="macros.xacro"/>

    <!-- COLOR -->
    <material name="red">
        <color rgba="1 0 0 1"/>
    </material>

    <material name="yellow">
        <color rgba="1 1 0.5 1"/>
    </material>


    <material name="green">
        <color rgba="0 1 0 1"/>
    </material>

    <material name="white">
        <color rgba="1 1 1 1" />
    </material>

    <material name="blue">
        <color rgba="0 0 1 1"/>
    </material>

    <material name="black">
        <color rgba="0 0 0 1"/>
    </material>

    <!-- BASE LINK -->
    <link name="base_link">
    </link>

    <!-- BODY LINK -->
    <joint name="body_joint" type="fixed">
        <parent link="base_link"/>
        <child link="body"/>
        <origin xyz="-0.12 0 0"/>
    </joint>

    <link name="body">
        <visual>
            <origin xyz="0.1 0 0.03"/>
            <geometry>
                <box size="0.2 0.1 0.06"/>
            </geometry>
            <material name="green"/>
        </visual>
        <collision>
            <origin xyz="0.1 0 0.03"/>
            <geometry>
                <box size="0.2 0.1 0.06"/>
            </geometry>
        </collision>
        <xacro:inertial_box mass="0.5" x="0.2" y="0.1" z="0.06">
            <origin xyz="0.1 0 0.03" rpy="0 0 0"/>
        </xacro:inertial_box>
    </link>

    <gazebo reference="body">
        <material>Gazebo/Green</material>
    </gazebo>

    <!-- LEFT WHEEL LINK -->
    <joint name="left_wheel_joint" type="continuous">
        <parent link="base_link"/>
        <child link="left_wheel"/>
        <origin xyz="0 0.065 0" rpy="-${pi/2} 0 0" />
        <axis xyz="0 0 1"/>
    </joint>

    <link name="left_wheel">
        <visual>
            <geometry>
                <cylinder radius="0.03" length="0.03"/>
            </geometry>
            <material name="blue"/>
        </visual>
        <collision>
            <geometry>
                <cylinder radius="0.03" length="0.03"/>
            </geometry>
        </collision>
        <xacro:inertial_cylinder mass="0.1" length="0.03" radius="0.03">
            <origin xyz="0 0 0" rpy="0 0 0"/>
        </xacro:inertial_cylinder>
    </link>

    <gazebo reference="left_wheel">
        <material>Gazebo/Black</material>
    </gazebo>

    <!-- RIGHT WHEEL LINK -->
    <joint name="right_wheel_joint" type="continuous">
        <parent link="base_link"/>
        <child link="right_wheel"/>
        <origin xyz="0 -0.065 0" rpy="${pi/2} 0 0" />
        <axis xyz="0 0 -1"/>
    </joint>

    <link name="right_wheel">
        <visual>
            <geometry>
                <cylinder radius="0.03" length="0.03"/>
            </geometry>
            <material name="blue"/>
        </visual>
        <collision>
            <geometry>
                <cylinder radius="0.03" length="0.03"/>
            </geometry>
        </collision>
        <xacro:inertial_cylinder mass="0.1" length="0.03" radius="0.03">
            <origin xyz="0 0 0" rpy="0 0 0"/>
        </xacro:inertial_cylinder>
    </link>

    <gazebo reference="right_wheel">
        <material>Gazebo/Black</material>
    </gazebo>

    <!-- CASTER WHEEL LINK -->
    <joint name="caster_wheel_joint" type="fixed">
        <parent link="body"/>
        <child link="caster_wheel"/>
        <origin xyz="0.03 0 0"/>
    </joint>

    <link name="caster_wheel">
        <visual>
            <geometry>
                <sphere radius="0.03"/>
            </geometry>
            <material name="black"/>
        </visual>
        <collision>
            <geometry>
                <sphere radius="0.03"/>
            </geometry>
        </collision>
        <xacro:inertial_sphere mass="10.1" radius="0.03">
            <origin xyz="0 0 0" rpy="0 0 0"/>
        </xacro:inertial_sphere>
    </link>

    <gazebo reference="caster_wheel">
        <material>Gazebo/Blue</material>

        <mu1 value="0.001"/>
        <mu2 value="0.001"/>
    </gazebo>

    <!-- LiDAR -->
    <joint name="laser_joint" type="fixed">
        <parent link="body"/>
        <child link="laser_frame"/>
        <origin xyz="0.1 0 0.075" rpy="0 0 0"/>
    </joint>

    <link name="laser_frame">
        <visual>
            <geometry>
                <cylinder radius="0.03" length="0.03"/>
            </geometry>
            <material name="red"/>
        </visual>
        <collision>
            <geometry>
                <cylinder radius="0.03" length="0.03"/>
            </geometry>
        </collision>
    </link>

    <!-- CAMERA -->

    <joint name="camera_joint" type="fixed">
        <parent link="body"/>
        <child link="camera_link"/>
        <origin xyz="0.20 0 0.03" rpy="0 0 0"/>
    </joint>

    <link name="camera_link">
        <visual>
            <geometry>
                <box size="0.01 0.03 0.03"/>
            </geometry>
            <material name="yellow"/>
        </visual>
        <collision>
            <geometry>
                <box size="0.01 0.03 0.03"/>
            </geometry>
        </collision>
    </link>

    <joint name="camera_optical_joint" type="fixed">
        <parent link="camera_link"/>
        <child link="camera_optical_frame"/>
        <origin xyz="0 0 0" rpy="${-pi/2} 0 ${-pi/2}"/>
    </joint>

    <link name="camera_optical_frame">
    </link>

    <!-- GUN -->
    <joint name="gun_joint" type="fixed">
        <parent link="camera_optical_frame"/>
        <child link="gun"/>
        <origin xyz="0.05 0 0" rpy="0 0 0"/>
    </joint>

    <link name="gun">
        <!-- 외부 원통 -->
        <visual>
            <origin xyz="0 0 0" rpy="0 0 0"/>
            <geometry>
                <cylinder radius="0.025" length="0.05"/> <!-- 외부 원통 -->
            </geometry>
            <material name="black"/> <!-- 검은색 유지 -->
        </visual>
        <collision>
            <origin xyz="0 0 0" rpy="0 0 0"/>
            <geometry>
                <cylinder radius="0.025" length="0.05"/>
            </geometry>
            <!-- 충돌 설정 -->
            <surface>
                <contact>
                    <ode>
                        <max_vel>1000</max_vel> <!-- 최대 속도 설정 -->
                        <min_depth>0.001</min_depth> <!-- 최소 깊이 설정 -->
                    </ode>
                </contact>
            </surface>
        </collision>
        
        <!-- 내부 구멍 (작은 원통) -->
        <visual>
            <origin xyz="0 0 0.02" rpy="0 0 0"/> <!-- 내부 구멍 위치 조정 -->
            <geometry>
                <cylinder radius="0.015" length="0.02"/> <!-- 내부 구멍 크기 -->
            </geometry>
            <material name="black"/>
        </visual>
        
        <!-- 관성 설정 -->
        <inertial>
            <mass value="0.5"/> <!-- 총의 질량 -->
            <inertia ixx="0.0001" iyy="0.0001" izz="0.0001" ixy="0" ixz="0" iyz="0"/>
        </inertial>
    </link>

    <!-- GAZEBO -->
    <xacro:include filename="gazebo.xacro"/>
    <xacro:include filename="lidar.xacro"/>
    <xacro:include filename="camera.xacro"/>
</robot>

